Workbook

Sheet Tổng quan
A1: TỔNG HỢP 126 TRƯỜNG ĐẠI HỌC / HỌC VIỆN - MIỀN → TỈNH/TP → TRƯỜNG
A2: Bấm tên trường để mở sheet ngành đào tạo; dùng nút [+]/[-] bên trái để mở/thu gọn. Tỉnh/TP: cột A theo 34 tỉnh/TP mới (từ 1/7/2025), cột C là tên cũ (63 tỉnh/TP). Miền Trung gồm cả Tây Nguyên. Nguồn danh sách trường và link: file 126_truong_TrangChu_va_TrangTuyenSinh.docx.
A4: Miền / Tỉnh-TP / Trường | B4: Số trường | C4: Tỉnh/TP (cũ) | D4: Viết tắt | E4: Số ngành | F4: Trạng thái dữ liệu | G4: Trang chủ | H4: Trang tuyển sinh | I4: Ghi chú
A5: MIỀN BẮC | B5: =B6+B58+B65+B69+B71+B73
A6: Hà Nội | B6: =COUNTA(A7:A57)
A7: Đại học Bách khoa Hà Nội (HUST) | C7: Hà Nội | D7: HUST | E7: =COUNTA(HUST!$B$11:$B$500) | F7: =IF(E7>0,"Đã có dữ liệu","Chưa có dữ liệu") | G7: https://hust.edu.vn/ | H7: https://ts.hust.edu.vn/
A8: Đại học Kinh tế Quốc dân (NEU) | C8: Hà Nội | D8: NEU | E8: =COUNTA(NEU!$B$11:$B$500) | F8: =IF(E8>0,"Đã có dữ liệu","Chưa có dữ liệu") | G8: https://neu.edu.vn/ | H8: https://daotao.neu.edu.vn/ hoặc https://xtkh.neu.edu.vn
A9: Đại học Ngoại thương (FTU) | C9: Hà Nội | D9: FTU | E9: =COUNTA(FTU!$B$11:$B$500) | F9: =IF(E9>0,"Đã có dữ liệu","Chưa có dữ liệu") | G9: https://ftu.edu.vn/ | H9: https://tuyensinh.ftu.edu.vn/ hoặc https://thongtintuyensinh.ftu.edu.vn/
A10: Đại học Thương mại (TMU) | C10: Hà Nội | D10: TMU | E10: =COUNTA(TMU!$B$11:$B$500) | F10: =IF(E10>0,"Đã có dữ liệu","Chưa có dữ liệu") | G10: https://tmu.edu.vn/ | H10: https://tuyensinh.tmu.edu.vn/
A11: Trường Đại học Luật Hà Nội (HLU) | C11: Hà Nội | D11: HLU | E11: =COUNTA(HLU!$B$11:$B$500) | F11: =IF(E11>0,"Đã có dữ liệu","Chưa có dữ liệu") | G11: https://hlu.edu.vn/ | H11: https://tuyensinh.hlu.edu.vn/
A12: Trường Đại học Khoa học Tự nhiên - ĐHQG Hà Nội (VNU-HUS) | C12: Hà Nội | D12: VNU-HUS | E12: =COUNTA('VNU-HUS'!$B$11:$B$500) | F12: =IF(E12>0,"Đã có dữ liệu","Chưa có dữ liệu") | G12: https://hus.vnu.edu.vn/ | H12: https://tuyensinh.hus.vnu.edu.vn/
A13: Trường Đại học Công nghệ - ĐHQG Hà Nội (VNU-UET) | C13: Hà Nội | D13: VNU-UET | E13: =COUNTA('VNU-UET'!$B$11:$B$500) | F13: =IF(E13>0,"Đã có dữ liệu","Chưa có dữ liệu") | G13: https://uet.vnu.edu.vn/ | H13: https://tuyensinh.uet.vnu.edu.vn/
A14: Trường Đại học Kinh tế - ĐHQG Hà Nội (VNU-UEB) | C14: Hà Nội | D14: VNU-UEB | E14: =COUNTA('VNU-UEB'!$B$11:$B$500) | F14: =IF(E14>0,"Đã có dữ liệu","Chưa có dữ liệu") | G14: https://ueb.vnu.edu.vn/ | H14: https://tuyensinh.ueb.edu.vn/
A15: Trường Đại học Khoa học Xã hội và Nhân văn - ĐHQG Hà Nội (VNU-USSH) | C15: Hà Nội | D15: VNU-USSH | E15: =COUNTA('VNU-USSH'!$B$11:$B$500) | F15: =IF(E15>0,"Đã có dữ liệu","Chưa có dữ liệu") | G15: https://ussh.vnu.edu.vn/ | H15: https://tuyensinh.ussh.edu.vn/
A16: Trường Đại học Ngoại ngữ - ĐHQG Hà Nội (VNU-ULIS) | C16: Hà Nội | D16: VNU-ULIS | E16: =COUNTA('VNU-ULIS'!$B$11:$B$500) | F16: =IF(E16>0,"Đã có dữ liệu","Chưa có dữ liệu") | G16: https://ulis.vnu.edu.vn/ | H16: https://tuyensinh.ulis.vnu.edu.vn/
A17: Trường Đại học Giáo dục - ĐHQG Hà Nội (VNU-UED) | C17: Hà Nội | D17: VNU-UED | E17: =COUNTA('VNU-UED'!$B$11:$B$500) | F17: =IF(E17>0,"Đã có dữ liệu","Chưa có dữ liệu") | G17: https://education.vnu.edu.vn/ | H17: https://education.vnu.edu.vn/
A18: Đại học Xây dựng Hà Nội (HUCE) | C18: Hà Nội | D18: HUCE | E18: =COUNTA(HUCE!$B$11:$B$500) | F18: =IF(E18>0,"Đã có dữ liệu","Chưa có dữ liệu") | G18: https://huce.edu.vn/ | H18: https://tuyensinh.huce.edu.vn/
A19: Trường Đại học Kiến trúc Hà Nội (HAU) | C19: Hà Nội | D19: HAU | E19: =COUNTA(HAU!$B$11:$B$500) | F19: =IF(E19>0,"Đã có dữ liệu","Chưa có dữ liệu") | G19: https://hau.edu.vn/ | H19: https://tuyensinh.hau.edu.vn/
A20: Trường Đại học Thủy lợi (TLU) | C20: Hà Nội | D20: TLU | E20: =COUNTA(TLU!$B$11:$B$500) | F20: =IF(E20>0,"Đã có dữ liệu","Chưa có dữ liệu") | G20: https://tlu.edu.vn/ | H20: https://tuyensinh.tlu.edu.vn/
A21: Trường Đại học Mỏ - Địa chất (HUMG) | C21: Hà Nội | D21: HUMG | E21: =COUNTA(HUMG!$B$11:$B$500) | F21: =IF(E21>0,"Đã có dữ liệu","Chưa có dữ liệu") | G21: https://humg.edu.vn/ | H21: https://tuyensinh.humg.edu.vn/
A22: Đại học Điện lực (EPU) | C22: Hà Nội | D22: EPU | E22: =COUNTA(EPU!$B$11:$B$500) | F22: =IF(E22>0,"Đã có dữ liệu","Chưa có dữ liệu") | G22: https://epu.edu.vn/ | H22: https://tuyensinh.epu.edu.vn/
A23: Trường Đại học Công nghiệp Hà Nội (HaUI) | C23: Hà Nội | D23: HaUI | E23: =COUNTA(HaUI!$B$11:$B$500) | F23: =IF(E23>0,"Đã có dữ liệu","Chưa có dữ liệu") | G23: https://haui.edu.vn/ | H23: https://tuyensinh.haui.edu.vn/
A24: Học viện Công nghệ Bưu chính Viễn thông (PTIT) | C24: Hà Nội | D24: PTIT | E24: =COUNTA(PTIT!$B$11:$B$500) | F24: =IF(E24>0,"Đã có dữ liệu","Chưa có dữ liệu") | G24: https://ptit.edu.vn/ | H24: https://tuyensinh.ptit.edu.vn/
A25: Học viện Kỹ thuật Mật mã (KMA) | C25: Hà Nội | D25: KMA | E25: =COUNTA(KMA!$B$11:$B$500) | F25: =IF(E25>0,"Đã có dữ liệu","Chưa có dữ liệu") | G25: https://actvn.edu.vn/ | H25: https://tuyensinh.actvn.edu.vn/
A26: Học viện Tài chính (AOF) | C26: Hà Nội | D26: AOF | E26: =COUNTA('HV Tài chính (AOF)'!$B$11:$B$500) | F26: =IF(E26>0,"Đã có dữ liệu","Chưa có dữ liệu") | G26: https://hvtc.edu.vn/ | H26: https://tuyensinh.hvtc.edu.vn/
A27: Học viện Ngân hàng (BA) | C27: Hà Nội | D27: BA | E27: =COUNTA('HV Ngân hàng (BA)'!$B$11:$B$500) | F27: =IF(E27>0,"Đã có dữ liệu","Chưa có dữ liệu") | G27: https://hvnh.edu.vn/ | H27: https://tuyensinh.hvnh.edu.vn/
A28: Học viện Ngoại giao (DAV) | C28: Hà Nội | D28: DAV | E28: =COUNTA('HV Ngoại giao (DAV)'!$B$11:$B$500) | F28: =IF(E28>0,"Đã có dữ liệu","Chưa có dữ liệu") | G28: https://dav.edu.vn/ | H28: https://tuyensinh.dav.edu.vn/
A29: Đại học Y Hà Nội (HMU) | C29: Hà Nội | D29: HMU | E29: =COUNTA(HMU!$B$11:$B$500) | F29: =IF(E29>0,"Đã có dữ liệu","Chưa có dữ liệu") | G29: https://hmu.edu.vn/ | H29: https://hmu.edu.vn/ (mục Tuyển sinh)
A30: Đại học Dược Hà Nội (HUP) | C30: Hà Nội | D30: HUP | E30: =COUNTA(HUP!$B$11:$B$500) | F30: =IF(E30>0,"Đã có dữ liệu","Chưa có dữ liệu") | G30: https://hup.edu.vn/ | H30: https://tuyensinh.hup.edu.vn/
A31: Đại học Y tế Công cộng (HUPH) | C31: Hà Nội | D31: HUPH | E31: =COUNTA(HUPH!$B$11:$B$500) | F31: =IF(E31>0,"Đã có dữ liệu","Chưa có dữ liệu") | G31: https://huph.edu.vn/ | H31: https://tuyensinh.huph.edu.vn/
A32: Trường Đại học Văn hóa Hà Nội (HUC) | C32: Hà Nội | D32: HUC | E32: =COUNTA(HUC!$B$11:$B$500) | F32: =IF(E32>0,"Đã có dữ liệu","Chưa có dữ liệu") | G32: https://huc.edu.vn/ | H32: https://tuyensinh.huc.edu.vn/
A33: Trường Đại học Mở Hà Nội (HOU) | C33: Hà Nội | D33: HOU | E33: =COUNTA(HOU!$B$11:$B$500) | F33: =IF(E33>0,"Đã có dữ liệu","Chưa có dữ liệu") | G33: https://hou.edu.vn/ | H33: https://tuyensinh.hou.edu.vn/
A34: Trường Đại học Lao động - Xã hội (ULSA) | C34: Hà Nội | D34: ULSA | E34: =COUNTA(ULSA!$B$11:$B$500) | F34: =IF(E34>0,"Đã có dữ liệu","Chưa có dữ liệu") | G34: https://ulsa.edu.vn/ | H34: https://tuyensinh.ulsa.edu.vn/
A35: Trường Đại học Giao thông Vận tải (UTC) | C35: Hà Nội | D35: UTC | E35: =COUNTA(UTC!$B$11:$B$500) | F35: =IF(E35>0,"Đã có dữ liệu","Chưa có dữ liệu") | G35: https://utc.edu.vn/ | H35: https://tuyensinh.utc.edu.vn/
A36: Trường Đại học Khoa học và Công nghệ Hà Nội (USTH) | C36: Hà Nội | D36: USTH | E36: =COUNTA(USTH!$B$11:$B$500) | F36: =IF(E36>0,"Đã có dữ liệu","Chưa có dữ liệu") | G36: https://usth.edu.vn/ | H36: https://tuyensinh.usth.edu.vn/
A37: Trường Đại học Phenikaa | C37: Hà Nội | E37: =COUNTA(Phenikaa!$B$11:$B$500) | F37: =IF(E37>0,"Đã có dữ liệu","Chưa có dữ liệu") | G37: https://phenikaa-uni.edu.vn/ | H37: https://tuyensinh.phenikaa-uni.edu.vn/
A38: Trường Đại học Thăng Long | C38: Hà Nội | E38: =COUNTA('Thăng Long'!$B$11:$B$500) | F38: =IF(E38>0,"Đã có dữ liệu","Chưa có dữ liệu") | G38: https://thanglong.edu.vn/ | H38: https://tuyensinh.thanglong.edu.vn/
A39: Trường Đại học CMC | C39: Hà Nội | E39: =COUNTA(CMC!$B$11:$B$500) | F39: =IF(E39>0,"Đã có dữ liệu","Chưa có dữ liệu") | G39: https://cmc-u.edu.vn/ | H39: https://tuyensinh.cmc-u.edu.vn/
A40: Trường Đại học Đại Nam | C40: Hà Nội | E40: =COUNTA('Đại Nam'!$B$11:$B$500) | F40: =IF(E40>0,"Đã có dữ liệu","Chưa có dữ liệu") | G40: https://dainam.edu.vn/ | H40: https://tuyensinh.dainam.edu.vn/
A41: Trường Đại học Kinh doanh và Công nghệ Hà Nội (HUBT) | C41: Hà Nội | D41: HUBT | E41: =COUNTA(HUBT!$B$11:$B$500) | F41: =IF(E41>0,"Đã có dữ liệu","Chưa có dữ liệu") | G41: https://hubt.edu.vn/ | H41: https://tuyensinh.hubt.edu.vn/
...

Sheet Danh sách 126 trường
A1: STT (file gốc) | B1: Tên trường | C1: Viết tắt | D1: Miền | E1: Tỉnh/TP (mới) | F1: Tỉnh/TP (cũ) | G1: Sheet ngành | H1: Số ngành | I1: Trang chủ | J1: Trang tuyển sinh | K1: Ghi chú
A2: 1 | B2: Đại học Bách khoa Hà Nội (HUST) | C2: HUST | D2: Miền Bắc | E2: Hà Nội | F2: Hà Nội | G2: HUST | H2: =COUNTA(HUST!$B$11:$B$500) | I2: https://hust.edu.vn/ | J2: https://ts.hust.edu.vn/
A3: 2 | B3: Đại học Kinh tế Quốc dân (NEU) | C3: NEU | D3: Miền Bắc | E3: Hà Nội | F3: Hà Nội | G3: NEU | H3: =COUNTA(NEU!$B$11:$B$500) | I3: https://neu.edu.vn/ | J3: https://daotao.neu.edu.vn/ hoặc https://xtkh.neu.edu.vn
A4: 3 | B4: Đại học Ngoại thương (FTU) | C4: FTU | D4: Miền Bắc | E4: Hà Nội | F4: Hà Nội | G4: FTU | H4: =COUNTA(FTU!$B$11:$B$500) | I4: https://ftu.edu.vn/ | J4: https://tuyensinh.ftu.edu.vn/ hoặc https://thongtintuyensinh.ftu.edu.vn/
A5: 4 | B5: Đại học Thương mại (TMU) | C5: TMU | D5: Miền Bắc | E5: Hà Nội | F5: Hà Nội | G5: TMU | H5: =COUNTA(TMU!$B$11:$B$500) | I5: https://tmu.edu.vn/ | J5: https://tuyensinh.tmu.edu.vn/
A6: 5 | B6: Trường Đại học Luật Hà Nội (HLU) | C6: HLU | D6: Miền Bắc | E6: Hà Nội | F6: Hà Nội | G6: HLU | H6: =COUNTA(HLU!$B$11:$B$500) | I6: https://hlu.edu.vn/ | J6: https://tuyensinh.hlu.edu.vn/
A7: 6 | B7: Trường Đại học Khoa học Tự nhiên - ĐHQG Hà Nội (VNU-HUS) | C7: VNU-HUS | D7: Miền Bắc | E7: Hà Nội | F7: Hà Nội | G7: VNU-HUS | H7: =COUNTA('VNU-HUS'!$B$11:$B$500) | I7: https://hus.vnu.edu.vn/ | J7: https://tuyensinh.hus.vnu.edu.vn/
A8: 7 | B8: Trường Đại học Công nghệ - ĐHQG Hà Nội (VNU-UET) | C8: VNU-UET | D8: Miền Bắc | E8: Hà Nội | F8: Hà Nội | G8: VNU-UET | H8: =COUNTA('VNU-UET'!$B$11:$B$500) | I8: https://uet.vnu.edu.vn/ | J8: https://tuyensinh.uet.vnu.edu.vn/
A9: 8 | B9: Trường Đại học Kinh tế - ĐHQG Hà Nội (VNU-UEB) | C9: VNU-UEB | D9: Miền Bắc | E9: Hà Nội | F9: Hà Nội | G9: VNU-UEB | H9: =COUNTA('VNU-UEB'!$B$11:$B$500) | I9: https://ueb.vnu.edu.vn/ | J9: https://tuyensinh.ueb.edu.vn/
A10: 9 | B10: Trường Đại học Khoa học Xã hội và Nhân văn - ĐHQG Hà Nội (VNU-USSH) | C10: VNU-USSH | D10: Miền Bắc | E10: Hà Nội | F10: Hà Nội | G10: VNU-USSH | H10: =COUNTA('VNU-USSH'!$B$11:$B$500) | I10: https://ussh.vnu.edu.vn/ | J10: https://tuyensinh.ussh.edu.vn/
A11: 10 | B11: Trường Đại học Ngoại ngữ - ĐHQG Hà Nội (VNU-ULIS) | C11: VNU-ULIS | D11: Miền Bắc | E11: Hà Nội | F11: Hà Nội | G11: VNU-ULIS | H11: =COUNTA('VNU-ULIS'!$B$11:$B$500) | I11: https://ulis.vnu.edu.vn/ | J11: https://tuyensinh.ulis.vnu.edu.vn/
A12: 11 | B12: Trường Đại học Giáo dục - ĐHQG Hà Nội (VNU-UED) | C12: VNU-UED | D12: Miền Bắc | E12: Hà Nội | F12: Hà Nội | G12: VNU-UED | H12: =COUNTA('VNU-UED'!$B$11:$B$500) | I12: https://education.vnu.edu.vn/ | J12: https://education.vnu.edu.vn/
A13: 12 | B13: Đại học Xây dựng Hà Nội (HUCE) | C13: HUCE | D13: Miền Bắc | E13: Hà Nội | F13: Hà Nội | G13: HUCE | H13: =COUNTA(HUCE!$B$11:$B$500) | I13: https://huce.edu.vn/ | J13: https://tuyensinh.huce.edu.vn/
A14: 13 | B14: Trường Đại học Kiến trúc Hà Nội (HAU) | C14: HAU | D14: Miền Bắc | E14: Hà Nội | F14: Hà Nội | G14: HAU | H14: =COUNTA(HAU!$B$11:$B$500) | I14: https://hau.edu.vn/ | J14: https://tuyensinh.hau.edu.vn/
A15: 14 | B15: Trường Đại học Thủy lợi (TLU) | C15: TLU | D15: Miền Bắc | E15: Hà Nội | F15: Hà Nội | G15: TLU | H15: =COUNTA(TLU!$B$11:$B$500) | I15: https://tlu.edu.vn/ | J15: https://tuyensinh.tlu.edu.vn/
A16: 15 | B16: Trường Đại học Mỏ - Địa chất (HUMG) | C16: HUMG | D16: Miền Bắc | E16: Hà Nội | F16: Hà Nội | G16: HUMG | H16: =COUNTA(HUMG!$B$11:$B$500) | I16: https://humg.edu.vn/ | J16: https://tuyensinh.humg.edu.vn/
A17: 16 | B17: Đại học Điện lực (EPU) | C17: EPU | D17: Miền Bắc | E17: Hà Nội | F17: Hà Nội | G17: EPU | H17: =COUNTA(EPU!$B$11:$B$500) | I17: https://epu.edu.vn/ | J17: https://tuyensinh.epu.edu.vn/
A18: 17 | B18: Trường Đại học Công nghiệp Hà Nội (HaUI) | C18: HaUI | D18: Miền Bắc | E18: Hà Nội | F18: Hà Nội | G18: HaUI | H18: =COUNTA(HaUI!$B$11:$B$500) | I18: https://haui.edu.vn/ | J18: https://tuyensinh.haui.edu.vn/
A19: 18 | B19: Học viện Công nghệ Bưu chính Viễn thông (PTIT) | C19: PTIT | D19: Miền Bắc | E19: Hà Nội | F19: Hà Nội | G19: PTIT | H19: =COUNTA(PTIT!$B$11:$B$500) | I19: https://ptit.edu.vn/ | J19: https://tuyensinh.ptit.edu.vn/
A20: 19 | B20: Học viện Kỹ thuật Mật mã (KMA) | C20: KMA | D20: Miền Bắc | E20: Hà Nội | F20: Hà Nội | G20: KMA | H20: =COUNTA(KMA!$B$11:$B$500) | I20: https://actvn.edu.vn/ | J20: https://tuyensinh.actvn.edu.vn/
A21: 20 | B21: Học viện Tài chính (AOF) | C21: AOF | D21: Miền Bắc | E21: Hà Nội | F21: Hà Nội | G21: HV Tài chính (AOF) | H21: =COUNTA('HV Tài chính (AOF)'!$B$11:$B$500) | I21: https://hvtc.edu.vn/ | J21: https://tuyensinh.hvtc.edu.vn/
A22: 21 | B22: Học viện Ngân hàng (BA) | C22: BA | D22: Miền Bắc | E22: Hà Nội | F22: Hà Nội | G22: HV Ngân hàng (BA) | H22: =COUNTA('HV Ngân hàng (BA)'!$B$11:$B$500) | I22: https://hvnh.edu.vn/ | J22: https://tuyensinh.hvnh.edu.vn/
A23: 22 | B23: Học viện Ngoại giao (DAV) | C23: DAV | D23: Miền Bắc | E23: Hà Nội | F23: Hà Nội | G23: HV Ngoại giao (DAV) | H23: =COUNTA('HV Ngoại giao (DAV)'!$B$11:$B$500) | I23: https://dav.edu.vn/ | J23: https://tuyensinh.dav.edu.vn/
A24: 23 | B24: Đại học Y Hà Nội (HMU) | C24: HMU | D24: Miền Bắc | E24: Hà Nội | F24: Hà Nội | G24: HMU | H24: =COUNTA(HMU!$B$11:$B$500) | I24: https://hmu.edu.vn/ | J24: https://hmu.edu.vn/ (mục Tuyển sinh)
A25: 24 | B25: Đại học Dược Hà Nội (HUP) | C25: HUP | D25: Miền Bắc | E25: Hà Nội | F25: Hà Nội | G25: HUP | H25: =COUNTA(HUP!$B$11:$B$500) | I25: https://hup.edu.vn/ | J25: https://tuyensinh.hup.edu.vn/
A26: 25 | B26: Đại học Y tế Công cộng (HUPH) | C26: HUPH | D26: Miền Bắc | E26: Hà Nội | F26: Hà Nội | G26: HUPH | H26: =COUNTA(HUPH!$B$11:$B$500) | I26: https://huph.edu.vn/ | J26: https://tuyensinh.huph.edu.vn/
A27: 26 | B27: Trường Đại học Văn hóa Hà Nội (HUC) | C27: HUC | D27: Miền Bắc | E27: Hà Nội | F27: Hà Nội | G27: HUC | H27: =COUNTA(HUC!$B$11:$B$500) | I27: https://huc.edu.vn/ | J27: https://tuyensinh.huc.edu.vn/
A28: 27 | B28: Trường Đại học Mở Hà Nội (HOU) | C28: HOU | D28: Miền Bắc | E28: Hà Nội | F28: Hà Nội | G28: HOU | H28: =COUNTA(HOU!$B$11:$B$500) | I28: https://hou.edu.vn/ | J28: https://tuyensinh.hou.edu.vn/
A29: 28 | B29: Trường Đại học Lao động - Xã hội (ULSA) | C29: ULSA | D29: Miền Bắc | E29: Hà Nội | F29: Hà Nội | G29: ULSA | H29: =COUNTA(ULSA!$B$11:$B$500) | I29: https://ulsa.edu.vn/ | J29: https://tuyensinh.ulsa.edu.vn/
A30: 29 | B30: Trường Đại học Giao thông Vận tải (UTC) | C30: UTC | D30: Miền Bắc | E30: Hà Nội | F30: Hà Nội | G30: UTC | H30: =COUNTA(UTC!$B$11:$B$500) | I30: https://utc.edu.vn/ | J30: https://tuyensinh.utc.edu.vn/
A31: 30 | B31: Trường Đại học Khoa học và Công nghệ Hà Nội (USTH) | C31: USTH | D31: Miền Bắc | E31: Hà Nội | F31: Hà Nội | G31: USTH | H31: =COUNTA(USTH!$B$11:$B$500) | I31: https://usth.edu.vn/ | J31: https://tuyensinh.usth.edu.vn/
A32: 31 | B32: Trường Đại học Phenikaa | D32: Miền Bắc | E32: Hà Nội | F32: Hà Nội | G32: Phenikaa | H32: =COUNTA(Phenikaa!$B$11:$B$500) | I32: https://phenikaa-uni.edu.vn/ | J32: https://tuyensinh.phenikaa-uni.edu.vn/
A33: 32 | B33: Trường Đại học Thăng Long | D33: Miền Bắc | E33: Hà Nội | F33: Hà Nội | G33: Thăng Long | H33: =COUNTA('Thăng Long'!$B$11:$B$500) | I33: https://thanglong.edu.vn/ | J33: https://tuyensinh.thanglong.edu.vn/
A34: 33 | B34: Trường Đại học CMC | D34: Miền Bắc | E34: Hà Nội | F34: Hà Nội | G34: CMC | H34: =COUNTA(CMC!$B$11:$B$500) | I34: https://cmc-u.edu.vn/ | J34: https://tuyensinh.cmc-u.edu.vn/
A35: 34 | B35: Trường Đại học Đại Nam | D35: Miền Bắc | E35: Hà Nội | F35: Hà Nội | G35: Đại Nam | H35: =COUNTA('Đại Nam'!$B$11:$B$500) | I35: https://dainam.edu.vn/ | J35: https://tuyensinh.dainam.edu.vn/
A36: 35 | B36: Trường Đại học Kinh doanh và Công nghệ Hà Nội (HUBT) | C36: HUBT | D36: Miền Bắc | E36: Hà Nội | F36: Hà Nội | G36: HUBT | H36: =COUNTA(HUBT!$B$11:$B$500) | I36: https://hubt.edu.vn/ | J36: https://tuyensinh.hubt.edu.vn/
A37: 36 | B37: Trường Đại học Công nghiệp Việt - Hung | D37: Miền Bắc | E37: Hà Nội | F37: Hà Nội | G37: Việt - Hung (VIU) | H37: =COUNTA('Việt - Hung (VIU)'!$B$11:$B$500) | I37: https://viu.edu.vn/ | J37: https://tuyensinh.viu.edu.vn/
A38: 37 | B38: Trường Đại học Kinh tế và Quản trị Kinh doanh - ĐH Thái Nguyên (TUEBA) | C38: TUEBA | D38: Miền Bắc | E38: Thái Nguyên | F38: Thái Nguyên | G38: TUEBA | H38: =COUNTA(TUEBA!$B$11:$B$500) | I38: https://tueba.edu.vn/ | J38: https://tuyensinh.tueba.edu.vn/
A39: 38 | B39: Trường Đại học Công nghệ Thông tin và Truyền thông - ĐH Thái Nguyên (ICTU) | C39: ICTU | D39: Miền Bắc | E39: Thái Nguyên | F39: Thái Nguyên | G39: ICTU | H39: =COUNTA(ICTU!$B$11:$B$500) | I39: https://ictu.edu.vn/ | J39: https://tuyensinh.ictu.edu.vn/
A40: 39 | B40: Trường Đại học Kỹ thuật Công nghiệp - ĐH Thái Nguyên (TNUT) | C40: TNUT | D40: Miền Bắc | E40: Thái Nguyên | F40: Thái Nguyên | G40: TNUT | H40: =COUNTA(TNUT!$B$11:$B$500) | I40: https://tnut.edu.vn/ | J40: https://tuyensinh.tnut.edu.vn/
...

Sheet HUST
A1: Đại học Bách khoa Hà Nội (HUST) | D1: ← Về Tổng quan
A2: Miền: | B2: Miền Bắc
A3: Tỉnh/TP (mới): | B3: Hà Nội
A4: Tỉnh/TP (cũ): | B4: Hà Nội
A5: Trang chủ: | B5: https://hust.edu.vn/
A6: Trang tuyển sinh: | B6: https://ts.hust.edu.vn/
A7: Nguồn/ghi chú: | B7: Danh sách chương trình đào tạo đại học chính quy 2026 (xét theo điểm thi THPT). Nguồn: huongnghiep.hocmai.vn/de-an/dai-hoc-bach-khoa-ha-noi (65 chương trình); FL4 lấy thêm từ diemthi.tuyensinh247.com. Trường công bố 68 chương trình, còn thiếu 2 chương trình chưa xác định. Mã là mã chương trình do trường quy định.
A10: STT | B10: Mã ngành | C10: Tên ngành (hệ chính quy)
A11: 1 | B11: BF-E12 | C11: Kỹ thuật Thực phẩm (CT tiên tiến)
A12: 2 | B12: BF-E19 | C12: Kỹ thuật sinh học (CT tiên tiến)
A13: 3 | B13: BF1 | C13: Kỹ thuật Sinh học
A14: 4 | B14: BF2 | C14: Kỹ thuật Thực phẩm
A15: 5 | B15: CH-E11 | C15: Kỹ thuật Hóa dược (CT tiên tiến)
A16: 6 | B16: CH1 | C16: Kỹ thuật Hoá học
A17: 7 | B17: CH2 | C17: Hoá học
A18: 8 | B18: ED2 | C18: Công nghệ giáo dục
A19: 9 | B19: ED3 | C19: Quản lý giáo dục
A20: 10 | B20: EE-E18 | C20: Hệ thống điện và năng lượng tái tạo (CT tiên tiến)
A21: 11 | B21: EE-E8 | C21: Kỹ thuật Điều khiển – Tự động hoá (CT tiên tiến)
A22: 12 | B22: EE-EP | C22: Tin học công nghiệp và Tự động hóa (Chương trình Việt – Pháp PFIEV)
... A76: 66 | B76: TX1 | C76: Công nghệ Dệt – May

Sheet NEU
A1: Đại học Kinh tế Quốc dân (NEU) | D1: ← Về Tổng quan
A2: Miền: | B2: Miền Bắc
A3: Tỉnh/TP (mới): | B3: Hà Nội
A4: Tỉnh/TP (cũ): | B4: Hà Nội
A5: Trang chủ: | B5: https://neu.edu.vn/
A6: Trang tuyển sinh: | B6: https://daotao.neu.edu.vn/ hoặc https://xtkh.neu.edu.vn
A7: Nguồn/ghi chú: | B7: Danh sách ngành/chương trình chính quy 2025-2026 (các mã chính). Nguồn tổng hợp từ daotao.neu.edu.vn, kenhtuyensinh.vn, thuvienphapluat.vn. Trường có ~88 mã CTĐT (gồm tiếng Anh, CLC, POHE, tiên tiến); liệt kê các mã ngành cốt lõi. Cập nhật 10/2026.
A10: STT | B10: Mã ngành | C10: Tên ngành (hệ chính quy)
A11: 1 | B11: 7220201 | C11: Ngôn ngữ Anh
A12: 2 | B12: 7310101 | C12: Kinh tế
A13: 3 | B13: 7310104 | C13: Kinh tế đầu tư
A14: 4 | B14: 7310105 | C14: Kinh tế phát triển
A15: 5 | B15: 7310106 | C15: Kinh tế quốc tế
A16: 6 | B16: 7310107 | C16: Thống kê kinh tế
A17: 7 | B17: 7310108 | C17: Toán kinh tế
A18: 8 | B18: 7320108 | C18: Quan hệ công chúng
A19: 9 | B19: 7340101 | C19: Quản trị kinh doanh
A20: 10 | B20: 7340115 | C20: Marketing
A21: 11 | B21: 7340116 | C21: Bất động sản
A22: 12 | B22: 7340120 | C22: Kinh doanh quốc tế
... A49: 39 | B49: 7340408 | C49: Quan hệ lao động

Sheet FTU
A1: Đại học Ngoại thương (FTU) | D1: ← Về Tổng quan
A2: Miền: | B2: Miền Bắc
A3: Tỉnh/TP (mới): | B3: Hà Nội
A4: Tỉnh/TP (cũ): | B4: Hà Nội
A5: Trang chủ: | B5: https://ftu.edu.vn/
A6: Trang tuyển sinh: | B6: https://tuyensinh.ftu.edu.vn/ hoặc https://thongtintuyensinh.ftu.edu.vn/
A7: Nguồn/ghi chú: | B7: Danh sách ngành/chương trình chính quy 2026 (Hà Nội + các CT chính). Nguồn: thongtintuyensinh.ftu.edu.vn, diemthi.tuyensinh247.com, các báo cáo điểm chuẩn 2026. Trường có nhiều CT (TC, CLC, TT, ĐHNNQT) thuộc các ngành trên. Cập nhật 10/2026.
A10: STT | B10: Mã ngành | C10: Tên ngành (hệ chính quy)
A11: 1 | B11: 7380101 | C11: Luật (Luật thương mại quốc tế - TC)
A12: 2 | B12: 7380109 | C12: Luật Thương mại quốc tế
A13: 3 | B13: 7310101 | C13: Kinh tế (Kinh tế đối ngoại - TC/CLC/TT)
A14: 4 | B14: 7310106 | C14: Kinh tế quốc tế
A15: 5 | B15: 7340120 | C15: Kinh doanh quốc tế (TC/CLC/TT i-Hons)
A16: 6 | B16: 7340101 | C16: Quản trị kinh doanh (TC/CLC/TT)
A17: 7 | B17: 7340201 | C17: Tài chính – Ngân hàng (TC/CLC/TT)
A18: 8 | B18: 7340301 | C18: Kế toán – Kiểm toán (TC)
A19: 9 | B19: 7810201 | C19: Quản trị khách sạn
A20: 10 | B20: 7510605 | C20: Logistics và Quản lý chuỗi cung ứng
A21: 11 | B21: 7480101 | C21: Khoa học máy tính / Khoa học dữ liệu / AI (CT mới 2026)
A22: 12 | B22: 7340115 | C22: Marketing / Truyền thông Marketing
... A24: 14 | B24: 7340122 | C24: Thương mại điện tử / Thương mại số

Sheet TMU
A1: Đại học Thương mại (TMU) | D1: ← Về Tổng quan
A2: Miền: | B2: Miền Bắc
A3: Tỉnh/TP (mới): | B3: Hà Nội
A4: Tỉnh/TP (cũ): | B4: Hà Nội
A5: Trang chủ: | B5: https://tmu.edu.vn/
A6: Trang tuyển sinh: | B6: https://tuyensinh.tmu.edu.vn/
A7: Nguồn/ghi chú: | B7: Danh sách ngành/chương trình chính quy 2026. Nguồn: tuyensinh.tmu.edu.vn (danh mục ngành 2026). Có các chương trình IPOP, chuẩn. Cập nhật 10/2026.
A10: STT | B10: Mã ngành | C10: Tên ngành (hệ chính quy)
A11: 1 | B11: TM01 | C11: Quản trị kinh doanh (Quản trị kinh doanh)
A12: 2 | B12: TM02 | C12: Quản trị kinh doanh (Quản trị kinh doanh - IPOP)
A13: 3 | B13: TM03 | C13: Quản trị kinh doanh (Khởi nghiệp và phát triển kinh doanh)
A14: 4 | B14: TM04 | C14: Quản trị khách sạn (Quản trị khách sạn)
A15: 5 | B15: TM05 | C15: Quản trị khách sạn (Quản trị khách sạn - IPOP)
A16: 6 | B16: TM06 | C16: Quản trị dịch vụ du lịch và lữ hành
A17: 7 | B17: TM07 | C17: Marketing (Marketing Thương mại)
A18: 8 | B18: TM08 | C18: Marketing (Marketing thương mại - IPOP)
A19: 9 | B19: TM09 | C19: Marketing (Marketing số)
A20: 10 | B20: TM10 | C20: Marketing (Quản trị Thương hiệu)
A21: 11 | B21: TM11 | C21: Marketing (Quản trị thương hiệu - IPOP)
A22: 12 | B22: TM12 | C22: Kế toán (Kế toán doanh nghiệp)
... A37: 27 | B37: 7480101 | C37: Khoa học máy tính (Ứng dụng trí tuệ nhân tạo trong kinh doanh)

Sheet HLU
A1: Trường Đại học Luật Hà Nội (HLU) | D1: ← Về Tổng quan
A2: Miền: | B2: Miền Bắc
A3: Tỉnh/TP (mới): | B3: Hà Nội
A4: Tỉnh/TP (cũ): | B4: Hà Nội
A5: Trang chủ: | B5: https://hlu.edu.vn/
A6: Trang tuyển sinh: | B6: https://tuyensinh.hlu.edu.vn/
A7: Nguồn/ghi chú: | B7: Danh sách ngành đào tạo đại học chính quy 2025 (Khóa 50). Nguồn: Quyết định 1650/QĐ-ĐHLHN ngày 12/6/2025 và tuyensinh.hlu.edu.vn. Cập nhật 10/2026. Năm 2026 dự kiến tương tự.
A10: STT | B10: Mã ngành | C10: Tên ngành (hệ chính quy)
A11: 1 | B11: 7380101 | C11: Luật
A12: 2 | B12: 7380107 | C12: Luật Kinh tế
A13: 3 | B13: 7380109 | C13: Luật Thương mại quốc tế
A14: 4 | B14: 7220201 | C14: Ngôn ngữ Anh
A15: 5 | B15: 7380101PH | C15: Luật (Phân hiệu Đắk Lắk)

Sheet VNU-HUS
A1: Trường Đại học Khoa học Tự nhiên - ĐHQG Hà Nội (VNU-HUS) | D1: ← Về Tổng quan
A2: Miền: | B2: Miền Bắc
A3: Tỉnh/TP (mới): | B3: Hà Nội
A4: Tỉnh/TP (cũ): | B4: Hà Nội
A5: Trang chủ: | B5: https://hus.vnu.edu.vn/
A6: Trang tuyển sinh: | B6: https://tuyensinh.hus.vnu.edu.vn/
A7: Nguồn/ghi chú: | B7: Danh sách ngành/CTĐT chính quy 2026. Nguồn: tuyensinh.hus.vnu.edu.vn (điểm chuẩn 2026) và các nguồn chính thức ĐHQGHN. Cập nhật 10/2026.
A10: STT | B10: Mã ngành | C10: Tên ngành (hệ chính quy)
A11: 1 | B11: QHT01 | C11: Toán học
A12: 2 | B12: QHT02 | C12: Toán tin
A13: 3 | B13: QHT03 | C13: Vật lý học
A14: 4 | B14: QHT04 | C14: Khoa học vật liệu
A15: 5 | B15: QHT05 | C15: Công nghệ kỹ thuật hạt nhân
A16: 6 | B16: QHT06 | C16: Hóa học
A17: 7 | B17: QHT07 | C17: Công nghệ kỹ thuật hóa học
A18: 8 | B18: QHT08 | C18: Sinh học
A19: 9 | B19: QHT09 | C19: Công nghệ sinh học
A20: 10 | B20: QHT10 | C20: Địa lý tự nhiên
A21: 11 | B21: QHT12 | C21: Quản lý đất đai
A22: 12 | B22: QHT13 | C22: Khoa học môi trường
... A37: 27 | B37: QHT98 | C37: Khoa học máy tính và thông tin

Sheet VNU-UET
A1: Trường Đại học Công nghệ - ĐHQG Hà Nội (VNU-UET) | D1: ← Về Tổng quan
A2: Miền: | B2: Miền Bắc
A3: Tỉnh/TP (mới): | B3: Hà Nội
A4: Tỉnh/TP (cũ): | B4: Hà Nội
A5: Trang chủ: | B5: https://uet.vnu.edu.vn/
A6: Trang tuyển sinh: | B6: https://tuyensinh.uet.vnu.edu.vn/
A7: Nguồn/ghi chú: | B7: Danh sách ngành chính quy 2026. Nguồn: uet.vnu.edu.vn (điểm chuẩn 2026 và danh mục ngành). Cập nhật 10/2026.
A10: STT | B10: Mã ngành | C10: Tên ngành (hệ chính quy)
A11: 1 | B11: CN1 | C11: Công nghệ thông tin
A12: 2 | B12: CN2 | C12: Kỹ thuật máy tính
A13: 3 | B13: CN3 | C13: Vật lý kỹ thuật
A14: 4 | B14: CN4 | C14: Cơ kỹ thuật
A15: 5 | B15: CN5 | C15: Công nghệ kỹ thuật xây dựng
A16: 6 | B16: CN6 | C16: Kỹ thuật cơ điện tử
A17: 7 | B17: CN7 | C17: Kỹ thuật không gian / Công nghệ hàng không vũ trụ
A18: 8 | B18: CN8 | C18: Khoa học máy tính
A19: 9 | B19: CN9 | C19: Kỹ thuật điện tử – viễn thông
A20: 10 | B20: CN10 | C20: Công nghệ nông nghiệp
A21: 11 | B21: CN11 | C21: Kỹ thuật điều khiển và tự động hoá
A22: 12 | B22: CN12 | C22: Trí tuệ nhân tạo
... A30: 20 | B30: CN21 | C30: Công nghệ sinh học

Sheet VNU-UEB
A1: Trường Đại học Kinh tế - ĐHQG Hà Nội (VNU-UEB) | D1: ← Về Tổng quan
A2: Miền: | B2: Miền Bắc
A3: Tỉnh/TP (mới): | B3: Hà Nội
A4: Tỉnh/TP (cũ): | B4: Hà Nội
A5: Trang chủ: | B5: https://ueb.vnu.edu.vn/
A6: Trang tuyển sinh: | B6: https://tuyensinh.ueb.edu.vn/
A7: Nguồn/ghi chú: | B7: Danh sách ngành chính quy 2026. Nguồn: đề án tuyển sinh UEB 2026, diemthi.tuyensinh247.com. Cập nhật 10/2026.
A10: STT | B10: Mã ngành | C10: Tên ngành (hệ chính quy)
A11: 1 | B11: 7310101 | C11: Kinh tế
A12: 2 | B12: 7310105 | C12: Kinh tế phát triển
A13: 3 | B13: 7310106 | C13: Kinh tế quốc tế
A14: 4 | B14: 7340101 | C14: Quản trị kinh doanh
A15: 5 | B15: 7340201 | C15: Tài chính – Ngân hàng
A16: 6 | B16: 7340301 | C16: Kế toán
A17: 7 | B17: 7340101.68 | C17: Quản trị kinh doanh (ĐH Troy - Hoa Kỳ)
A18: 8 | B18: 7340101.98 | C18: Quản trị kinh doanh (ĐH St. Francis - Hoa Kỳ)

Sheet VNU-USSH
A1: Trường Đại học Khoa học Xã hội và Nhân văn - ĐHQG Hà Nội (VNU-USSH) | D1: ← Về Tổng quan
A2: Miền: | B2: Miền Bắc
A3: Tỉnh/TP (mới): | B3: Hà Nội
A4: Tỉnh/TP (cũ): | B4: Hà Nội
A5: Trang chủ: | B5: https://ussh.vnu.edu.vn/
A6: Trang tuyển sinh: | B6: https://tuyensinh.ussh.edu.vn/
A7: Nguồn/ghi chú: | B7: Danh sách ngành chính quy 2025-2026. Nguồn: điểm chuẩn 2026 và danh mục ngành USSH. Cập nhật 10/2026.
A10: STT | B10: Mã ngành | C10: Tên ngành (hệ chính quy)
A11: 1 | B11: QHX01 | C11: Báo chí
A12: 2 | B12: QHX02 | C12: Chính trị học
A13: 3 | B13: QHX03 | C13: Công tác xã hội
A14: 4 | B14: QHX04 | C14: Điện ảnh và nghệ thuật đại chúng
A15: 5 | B15: QHX05 | C15: Đông Nam Á học
A16: 6 | B16: QHX06 | C16: Đông phương học
A17: 7 | B17: QHX07 | C17: Hán Nôm
A18: 8 | B18: QHX08 | C18: Hàn Quốc học
A19: 9 | B19: QHX09 | C19: Khoa học quản lý
A20: 10 | B20: QHX10 | C20: Lịch sử
A21: 11 | B21: QHX11 | C21: Lưu trữ học
A22: 12 | B22: QHX12 | C22: Ngôn ngữ học
... A38: 28 | B38: QHX28 | C38: Xã hội học

Sheet VNU-ULIS
A1: Trường Đại học Ngoại ngữ - ĐHQG Hà Nội (VNU-ULIS) | D1: ← Về Tổng quan
A2: Miền: | B2: Miền Bắc
A3: Tỉnh/TP (mới): | B3: Hà Nội
A4: Tỉnh/TP (cũ): | B4: Hà Nội
A5: Trang chủ: | B5: https://ulis.vnu.edu.vn/
A6: Trang tuyển sinh: | B6: https://tuyensinh.ulis.vnu.edu.vn/
A7: Nguồn/ghi chú: | B7: Danh sách ngành chính quy 2025-2026. Nguồn: đề án ULIS và các trang tuyển sinh. Cập nhật 10/2026.
A10: STT | B10: Mã ngành | C10: Tên ngành (hệ chính quy)
A11: 1 | B11: 7140231 | C11: Sư phạm tiếng Anh
A12: 2 | B12: 7140234 | C12: Sư phạm tiếng Trung Quốc
A13: 3 | B13: 7140235 | C13: Sư phạm tiếng Đức
A14: 4 | B14: 7140236 | C14: Sư phạm tiếng Nhật
A15: 5 | B15: 7140237 | C15: Sư phạm tiếng Hàn Quốc
A16: 6 | B16: 7220101 | C16: Tiếng Việt và Văn hóa Việt Nam
A17: 7 | B17: 7220201 | C17: Ngôn ngữ Anh
A18: 8 | B18: 7220202 | C18: Ngôn ngữ Nga
A19: 9 | B19: 7220203 | C19: Ngôn ngữ Pháp
A20: 10 | B20: 7220204 | C20: Ngôn ngữ Trung Quốc
A21: 11 | B21: 7220205 | C21: Ngôn ngữ Đức
A22: 12 | B22: 7220209 | C22: Ngôn ngữ Nhật
... A26: 16 | B26: 7320107 | C26: Truyền thông quốc tế

Sheet VNU-UED
A1: Trường Đại học Giáo dục - ĐHQG Hà Nội (VNU-UED) | D1: ← Về Tổng quan
A2: Miền: | B2: Miền Bắc
A3: Tỉnh/TP (mới): | B3: Hà Nội
A4: Tỉnh/TP (cũ): | B4: Hà Nội
A5: Trang chủ: | B5: https://education.vnu.edu.vn/
A6: Trang tuyển sinh: | B6: https://education.vnu.edu.vn/
A7: Nguồn/ghi chú: | B7: Danh sách ngành chính quy 2026. Nguồn: các trang tuyển sinh UED/ĐHQGHN. Cập nhật 10/2026.
A10: STT | B10: Mã ngành | C10: Tên ngành (hệ chính quy)
A11: 1 | B11: 7140209 | C11: Sư phạm Toán học
A12: 2 | B12: 7140211 | C12: Sư phạm Vật lí
A13: 3 | B13: 7140212 | C13: Sư phạm Hóa học
A14: 4 | B14: 7140213 | C14: Sư phạm Sinh học
A15: 5 | B15: 7140247 | C15: Sư phạm Khoa học Tự nhiên
A16: 6 | B16: 7140217 | C16: Sư phạm Ngữ văn
A17: 7 | B17: 7140218 | C17: Sư phạm Lịch sử
A18: 8 | B18: 7140249 | C18: Sư phạm Lịch sử - Địa lý
A19: 9 | B19: 7140201 | C19: Giáo dục Mầm non
A20: 10 | B20: 7140202 | C20: Giáo dục Tiểu học
A21: 11 | B21: 7140102 | C21: Khoa học giáo dục
A22: 12 | B22: 7140103 | C22: Quản trị chất lượng giáo dục
... A26: 16 | B26: 7310402 | C26: Tham vấn học đường

Sheet HUCE
A1: Đại học Xây dựng Hà Nội (HUCE) | D1: ← Về Tổng quan
A2: Miền: | B2: Miền Bắc
A3: Tỉnh/TP (mới): | B3: Hà Nội
A4: Tỉnh/TP (cũ): | B4: Hà Nội
A5: Trang chủ: | B5: https://huce.edu.vn/
A6: Trang tuyển sinh: | B6: https://tuyensinh.huce.edu.vn/
A7: Nguồn/ghi chú: | B7: Danh sách ngành/chuyên ngành chính quy 2026 (từ bảng điểm chuẩn). Nguồn: thông báo điểm chuẩn HUCE 2026. Cập nhật 10/2026.
A10: STT | B10: Mã ngành | C10: Tên ngành (hệ chính quy)
A11: 1 | B11: XDA01 | C11: Kiến trúc
A12: 2 | B12: XDA02 | C12: Kiến trúc / Kiến trúc công nghệ
A13: 3 | B13: XDA03 | C13: Kiến trúc cảnh quan
A14: 4 | B14: XDA04 | C14: Kiến trúc nội thất
A15: 5 | B15: XDA05 | C15: Quy hoạch vùng và đô thị
A16: 6 | B16: XDA06 | C16: Mỹ thuật đô thị
A17: 7 | B17: XDA07 | C17: Kỹ thuật xây dựng
A18: 8 | B18: XDA08 | C18: Kỹ thuật xây dựng / Xây dựng dân dụng và công nghiệp
A19: 9 | B19: XDA09 | C19: Kỹ thuật xây dựng / Hệ thống kỹ thuật trong công trình
A20: 10 | B20: XDA10 | C20: Kỹ thuật xây dựng / Tin học xây dựng
A21: 11 | B21: XDA11 | C21: Kỹ thuật xây dựng / Kỹ thuật công trình biển
A22: 12 | B22: XDA12 | C22: Kỹ thuật xây dựng công trình thủy
... A40: 30 | B40: XDA41 | C40: Nghệ thuật và thiết kế

Sheet HAU
A1: Trường Đại học Kiến trúc Hà Nội (HAU) | D1: ← Về Tổng quan
A2: Miền: | B2: Miền Bắc
A3: Tỉnh/TP (mới): | B3: Hà Nội
A4: Tỉnh/TP (cũ): | B4: Hà Nội
A5: Trang chủ: | B5: https://hau.edu.vn/
A6: Trang tuyển sinh: | B6: https://tuyensinh.hau.edu.vn/
A7: Nguồn/ghi chú: | B7: Danh sách ngành/chuyên ngành chính quy 2026. Nguồn: thông báo điểm chuẩn HAU 2026 và danh mục ngành. Cập nhật 10/2026.
A10: STT | B10: Mã ngành | C10: Tên ngành (hệ chính quy)
A11: 1 | B11: 7580101 | C11: Kiến trúc
A12: 2 | B12: 7580101_1 | C12: Kiến trúc (Chương trình tiên tiến)
A13: 3 | B13: 7580102 | C13: Kiến trúc cảnh quan
A14: 4 | B14: 7580105 | C14: Quy hoạch vùng và đô thị
A15: 5 | B15: 7580105_1 | C15: Quy hoạch vùng và đô thị (Thiết kế đô thị)
A16: 6 | B16: 7210105 | C16: Điêu khắc
A17: 7 | B17: 7210105_1 | C17: Mỹ thuật đô thị
A18: 8 | B18: 7580210 | C18: Kỹ thuật cơ sở hạ tầng (Hạ tầng đô thị)
A19: 9 | B19: 7580210_1 | C19: Kỹ thuật cơ sở hạ tầng (Môi trường đô thị)
A20: 10 | B20: 7580210_2 | C20: Kỹ thuật cơ sở hạ tầng (Công nghệ cơ điện công trình)
A21: 11 | B21: 7580213 | C21: Kỹ thuật cấp thoát nước
A22: 12 | B22: 7210403 | C22: Thiết kế đồ họa
... A38: 28 | B38: 7310105 | C38: Kinh tế phát triển

Sheet TLU
A1: Trường Đại học Thủy lợi (TLU) | D1: ← Về Tổng quan
A2: Miền: | B2: Miền Bắc
A3: Tỉnh/TP (mới): | B3: Hà Nội
A4: Tỉnh/TP (cũ): | B4: Hà Nội
A5: Trang chủ: | B5: https://tlu.edu.vn/
A6: Trang tuyển sinh: | B6: https://tuyensinh.tlu.edu.vn/
A7: Nguồn/ghi chú: | B7: Danh sách ngành chính quy 2026. Nguồn: đề án và danh mục ngành TLU. Cập nhật 10/2026.
A10: STT | B10: Mã ngành | C10: Tên ngành (hệ chính quy)
A11: 1 | B11: TLA101 | C11: Kỹ thuật xây dựng công trình thủy
A12: 2 | B12: TLA102 | C12: Kỹ thuật tài nguyên nước
A13: 3 | B13: TLA103 | C13: Tài nguyên nước và môi trường (Thủy văn học)
A14: 4 | B14: TLA104 | C14: Kỹ thuật xây dựng dân dụng và công nghiệp
A15: 5 | B15: TLA105 | C15: Kỹ thuật cơ khí
A16: 6 | B16: TLA106 | C16: Công nghệ thông tin
A17: 7 | B17: TLA107 | C17: Kỹ thuật cấp thoát nước
A18: 8 | B18: TLA109 | C18: Kỹ thuật môi trường
A19: 9 | B19: TLA110 | C19: Kỹ thuật cơ sở hạ tầng
A20: 10 | B20: TLA111 | C20: Công nghệ kỹ thuật xây dựng
A21: 11 | B21: TLA112 | C21: Kỹ thuật điện
A22: 12 | B22: TLA113 | C22: Kỹ thuật xây dựng công trình giao thông
... A48: 38 | B48: TLA410 | C48: Kinh tế số

Sheet HUMG
A1: Trường Đại học Mỏ - Địa chất (HUMG) | D1: ← Về Tổng quan
A2: Miền: | B2: Miền Bắc
A3: Tỉnh/TP (mới): | B3: Hà Nội
A4: Tỉnh/TP (cũ): | B4: Hà Nội
A5: Trang chủ: | B5: https://humg.edu.vn/
A6: Trang tuyển sinh: | B6: https://tuyensinh.humg.edu.vn/
A7: Nguồn/ghi chú: | B7: Danh sách ngành chính quy 2025-2026. Nguồn: danh mục ngành HUMG. Cập nhật 10/2026.
A10: STT | B10: Mã ngành | C10: Tên ngành (hệ chính quy)
A11: 1 | B11: 7440201 | C11: Địa chất học
A12: 2 | B12: 7440229 | C12: Quản lý và phân tích dữ liệu khoa học trái đất
A13: 3 | B13: 7460108 | C13: Khoa học dữ liệu
A14: 4 | B14: 7480201 | C14: Công nghệ thông tin
A15: 5 | B15: 7480206 | C15: Địa tin học
A16: 6 | B16: 7510401 | C16: Công nghệ kỹ thuật hóa học
A17: 7 | B17: 7520103 | C17: Kỹ thuật cơ khí
A18: 8 | B18: 7520107 | C18: Kỹ thuật Robot
A19: 9 | B19: 7520114 | C19: Kỹ thuật cơ điện tử
A20: 10 | B20: 7520201 | C20: Kỹ thuật điện
A21: 11 | B21: 7520216 | C21: Kỹ thuật điều khiển và tự động hóa
A22: 12 | B22: 7520301 | C22: Kỹ thuật hóa học (CT tiên tiến)
... A44: 34 | B44: 7220204 | C44: Ngôn ngữ Trung Quốc

Sheet EPU
A1: Đại học Điện lực (EPU) | D1: ← Về Tổng quan
A2: Miền: | B2: Miền Bắc
A3: Tỉnh/TP (mới): | B3: Hà Nội
A4: Tỉnh/TP (cũ): | B4: Hà Nội
A5: Trang chủ: | B5: https://epu.edu.vn/
A6: Trang tuyển sinh: | B6: https://tuyensinh.epu.edu.vn/
A7: Nguồn/ghi chú: | B7: Danh sách ngành chính quy 2025-2026. Nguồn: các trang tuyển sinh EPU. Cập nhật 10/2026.
A10: STT | B10: Mã ngành | C10: Tên ngành (hệ chính quy)
A11: 1 | B11: 7510301 | C11: Công nghệ kỹ thuật điện, điện tử
A12: 2 | B12: 7510303 | C12: Công nghệ kỹ thuật điều khiển và tự động hoá
A13: 3 | B13: 7510302 | C13: Công nghệ kỹ thuật điện tử - viễn thông
A14: 4 | B14: 7480201 | C14: Công nghệ thông tin
A15: 5 | B15: 7480107 | C15: Trí tuệ nhân tạo
A16: 6 | B16: 7480106 | C16: Kỹ thuật máy tính
A17: 7 | B17: 7510203 | C17: Công nghệ kỹ thuật cơ điện tử
A18: 8 | B18: 7510201 | C18: Công nghệ kỹ thuật cơ khí
A19: 9 | B19: 7510205 | C19: Công nghệ kỹ thuật ô tô
A20: 10 | B20: 7520115 | C20: Kỹ thuật nhiệt
A21: 11 | B21: 7520107 | C21: Kỹ thuật Robot
A22: 12 | B22: 7340101 | C22: Quản trị kinh doanh
... A33: 23 | B33: 7220201 | C33: Ngôn ngữ Anh

Sheet HaUI
A1: Trường Đại học Công nghiệp Hà Nội (HaUI) | D1: ← Về Tổng quan
A2: Miền: | B2: Miền Bắc
A3: Tỉnh/TP (mới): | B3: Hà Nội
A4: Tỉnh/TP (cũ): | B4: Hà Nội
A5: Trang chủ: | B5: https://haui.edu.vn/
A6: Trang tuyển sinh: | B6: https://tuyensinh.haui.edu.vn/
A7: Nguồn/ghi chú: | B7: Danh sách ngành/chương trình đào tạo đại học chính quy 2026 (theo bảng xét tuyển kết hợp). Nguồn: huongnghiep.hocmai.vn/de-an/truong-dai-hoc-cong-nghiep-ha-noi. Trường công bố 71 ngành/chương trình, nguồn liệt kê 70 -> còn thiếu 1 chương trình chưa xác định.
A10: STT | B10: Mã ngành | C10: Tên ngành (hệ chính quy)
A11: 1 | B11: 7210404 | C11: Thiết kế thời trang
A12: 2 | B12: 7220201 | C12: Ngôn ngữ Anh
A13: 3 | B13: 7220204 | C13: Ngôn ngữ Trung Quốc
A14: 4 | B14: 7220204LK | C14: Ngôn ngữ Trung Quốc (LK2+2 với ĐHKHKT Quảng Tây)
A15: 5 | B15: 7220209 | C15: Ngôn ngữ Nhật
A16: 6 | B16: 7220210 | C16: Ngôn ngữ Hàn Quốc
A17: 7 | B17: 7229020 | C17: Ngôn ngữ học
A18: 8 | B18: 7310104 | C18: Kinh tế đầu tư
A19: 9 | B19: 7310612 | C19: Trung Quốc học
A20: 10 | B20: 7340101 | C20: Quản trị kinh doanh
A21: 11 | B21: 73401012 | C21: Phân tích dữ liệu kinh doanh
A22: 12 | B22: 7340101TA | C22: Quản trị kinh doanh (CTĐT bằng Tiếng Anh)
... A80: 70 | B80: 7810202TA | C80: Quản trị nhà hàng và dịch vụ ăn uống (CTĐT bằng tiếng Anh)

Sheet PTIT
A1: Học viện Công nghệ Bưu chính Viễn thông (PTIT) | D1: ← Về Tổng quan
A2: Miền: | B2: Miền Bắc
A3: Tỉnh/TP (mới): | B3: Hà Nội
A4: Tỉnh/TP (cũ): | B4: Hà Nội
A5: Trang chủ: | B5: https://ptit.edu.vn/
A6: Trang tuyển sinh: | B6: https://tuyensinh.ptit.edu.vn/
A7: Nguồn/ghi chú: | B7: Danh sách ngành/chương trình chính quy 2026 (cơ sở Hà Nội). Nguồn: ptit.edu.vn và các trang tuyển sinh. Cập nhật 10/2026.
A10: STT | B10: Mã ngành | C10: Tên ngành (hệ chính quy)
A11: 1 | B11: 7520207 | C11: Kỹ thuật Điện tử viễn thông
A12: 2 | B12: 7520207AT | C12: Trí tuệ nhân tạo vạn vật (AIoT)
A13: 3 | B13: 7520216 | C13: Kỹ thuật Điều khiển và tự động hóa
A14: 4 | B14: 7510301 | C14: Công nghệ Kỹ thuật Điện, điện tử
A15: 5 | B15: 7510301VM | C15: Công nghệ vi mạch bán dẫn
A16: 6 | B16: 7480201 | C16: Công nghệ thông tin
A17: 7 | B17: 7480107 | C17: Trí tuệ nhân tạo
A18: 8 | B18: 7480202 | C18: An toàn thông tin
A19: 9 | B19: 7480101 | C19: Khoa học máy tính / Khoa học dữ liệu
A20: 10 | B20: 7480102 | C20: Kỹ thuật dữ liệu
A21: 11 | B21: 7520208 | C21: Công nghệ Internet vạn vật (IoT)
A22: 12 | B22: 7340101 | C22: Quản trị kinh doanh
... A27: 17 | B27: 7329001 | C27: Công nghệ đa phương tiện

Sheet KMA
A1: Học viện Kỹ thuật Mật mã (KMA) | D1: ← Về Tổng quan
A2: Miền: | B2: Miền Bắc
A3: Tỉnh/TP (mới): | B3: Hà Nội
A4: Tỉnh/TP (cũ): | B4: Hà Nội
A5: Trang chủ: | B5: https://actvn.edu.vn/
A6: Trang tuyển sinh: | B6: https://tuyensinh.actvn.edu.vn/
A7: Nguồn/ghi chú: | B7: Danh sách ngành chính quy 2026 (3 ngành chính). Nguồn: actvn.edu.vn và các trang tuyển sinh. Cập nhật 10/2026.
A10: STT | B10: Mã ngành | C10: Tên ngành (hệ chính quy)
A11: 1 | B11: 7480201 | C11: Công nghệ thông tin
A12: 2 | B12: 7480202 | C12: An toàn thông tin
A13: 3 | B13: 7520207 | C13: Kỹ thuật Điện tử – Viễn thông

Sheet HV Tài chính (AOF)
A1: Học viện Tài chính (AOF) | D1: ← Về Tổng quan
A2: Miền: | B2: Miền Bắc
A3: Tỉnh/TP (mới): | B3: Hà Nội
A4: Tỉnh/TP (cũ): | B4: Hà Nội
A5: Trang chủ: | B5: https://hvtc.edu.vn/
A6: Trang tuyển sinh: | B6: https://tuyensinh.hvtc.edu.vn/
A7: Nguồn/ghi chú: | B7: Danh sách ngành chính quy 2025-2026. Nguồn: các trang tuyển sinh HV Tài chính. Cập nhật 10/2026.
A10: STT | B10: Mã ngành | C10: Tên ngành (hệ chính quy)
A11: 1 | B11: 7220201 | C11: Ngôn ngữ Anh (Tiếng Anh tài chính kế toán)
A12: 2 | B12: 7310101 | C12: Kinh tế và quản lý nguồn lực tài chính
A13: 3 | B13: 7310102 | C13: Kinh tế chính trị - tài chính
A14: 4 | B14: 7310104 | C14: Kinh tế đầu tư
A15: 5 | B15: 7310108 | C15: Toán tài chính
A16: 6 | B16: 7340101 | C16: Quản trị doanh nghiệp / Quản trị kinh doanh
A17: 7 | B17: 7340115 | C17: Marketing
A18: 8 | B18: 7340116 | C18: Thẩm định giá và kinh doanh bất động sản
A19: 9 | B19: 7340120 | C19: Kinh doanh quốc tế
A20: 10 | B20: 7340201 | C20: Tài chính - Ngân hàng (các chuyên ngành)
A21: 11 | B21: 7340204 | C21: Tài chính bảo hiểm
A22: 12 | B22: 7340301 | C22: Kế toán (doanh nghiệp, công)
A23: 13 | B23: 7340302 | C23: Kiểm toán

Sheet HV Ngân hàng (BA)
A1: Học viện Ngân hàng (BA) | D1: ← Về Tổng quan
A2: Miền: | B2: Miền Bắc
A3: Tỉnh/TP (mới): | B3: Hà Nội
A4: Tỉnh/TP (cũ): | B4: Hà Nội
A5: Trang chủ: | B5: https://hvnh.edu.vn/
A6: Trang tuyển sinh: | B6: https://tuyensinh.hvnh.edu.vn/
A7: Nguồn/ghi chú: | B7: Danh sách ngành/chương trình chính quy 2026. Nguồn: các trang tuyển sinh HV Ngân hàng. Cập nhật 10/2026.
A10: STT | B10: Mã ngành | C10: Tên ngành (hệ chính quy)
A11: 1 | B11: ACT01 | C11: Kế toán (Chất lượng cao)
A12: 2 | B12: ACT02 | C12: Kế toán
A13: 3 | B13: ACT03 | C13: Kế toán (Liên kết ĐH Sunderland)
A14: 4 | B14: ACT04 | C14: Kiểm toán
A15: 5 | B15: ACT05 | C15: Kiểm toán (Chất lượng cao)
A16: 6 | B16: ACT06 | C16: Kế toán (Định hướng Nhật Bản)
A17: 7 | B17: BANK01 | C17: Ngân hàng (Chất lượng cao)
A18: 8 | B18: BANK02 | C18: Ngân hàng
A19: 9 | B19: BANK03 | C19: Ngân hàng số
A20: 10 | B20: BANK04 | C20: Tài chính-Ngân hàng (Liên kết Sunderland)
A21: 11 | B21: BANK06 | C21: Ngân hàng và Tài chính quốc tế (CLC)
A22: 12 | B22: BANK07 | C22: Ngân hàng trung ương và chính sách công (CLC)
... A31: 21 | B31: DS01 | C31: Khoa học dữ liệu trong kinh tế và kinh doanh

Sheet HV Ngoại giao (DAV)
A1: Học viện Ngoại giao (DAV) | D1: ← Về Tổng quan
A2: Miền: | B2: Miền Bắc
A3: Tỉnh/TP (mới): | B3: Hà Nội
A4: Tỉnh/TP (cũ): | B4: Hà Nội
A5: Trang chủ: | B5: https://dav.edu.vn/
A6: Trang tuyển sinh: | B6: https://tuyensinh.dav.edu.vn/
A7: Nguồn/ghi chú: | B7: Danh sách ngành chính quy 2026. Nguồn: điểm chuẩn và danh mục DAV. Cập nhật 10/2026.
A10: STT | B10: Mã ngành | C10: Tên ngành (hệ chính quy)
A11: 1 | B11: HQT01 | C11: Quan hệ quốc tế
A12: 2 | B12: HQT02 | C12: Ngôn ngữ Anh
A13: 3 | B13: HQT03 | C13: Kinh tế quốc tế
A14: 4 | B14: HQT04 | C14: Luật quốc tế
A15: 5 | B15: HQT05 | C15: Truyền thông quốc tế
A16: 6 | B16: HQT06 | C16: Kinh doanh quốc tế
A17: 7 | B17: HQT07 | C17: Luật thương mại quốc tế
A18: 8 | B18: HQT08 | C18: Hàn Quốc học
A19: 9 | B19: HQT09 | C19: Hoa Kỳ học
A20: 10 | B20: HQT10 | C20: Nhật Bản học
A21: 11 | B21: HQT11 | C21: Trung Quốc học

Sheet HMU
A1: Đại học Y Hà Nội (HMU) | D1: ← Về Tổng quan
A2: Miền: | B2: Miền Bắc
A3: Tỉnh/TP (mới): | B3: Hà Nội
A4: Tỉnh/TP (cũ): | B4: Hà Nội
A5: Trang chủ: | B5: https://hmu.edu.vn/
A6: Trang tuyển sinh: | B6: https://hmu.edu.vn/ (mục Tuyển sinh)
A7: Nguồn/ghi chú: | B7: Danh sách ngành chính quy 2026. Nguồn: đề án và điểm chuẩn HMU. Cập nhật 10/2026.
A10: STT | B10: Mã ngành | C10: Tên ngành (hệ chính quy)
A11: 1 | B11: 7720101 | C11: Y khoa
A12: 2 | B12: 7720101YHT | C12: Y khoa (Phân hiệu Thanh Hóa)
A13: 3 | B13: 7720501 | C13: Răng-Hàm-Mặt
A14: 4 | B14: 7720115 | C14: Y học cổ truyền
A15: 5 | B15: 7720110 | C15: Y học dự phòng
A16: 6 | B16: 7720301 | C16: Điều dưỡng (Chương trình tiên tiến)
A17: 7 | B17: 7720301YHT | C17: Điều dưỡng (Phân hiệu Thanh Hóa)
A18: 8 | B18: 7720302 | C18: Hộ sinh
A19: 9 | B19: 7720502 | C19: Kỹ thuật phục hình răng
A20: 10 | B20: 7720601 | C20: Kỹ thuật xét nghiệm y học
A21: 11 | B21: 7720602 | C21: Kỹ thuật hình ảnh y học
A22: 12 | B22: 7720603 | C22: Kỹ thuật phục hồi chức năng
... A27: 17 | B27: 7760101 | C27: Công tác xã hội

Sheet HUP
A1: Đại học Dược Hà Nội (HUP) | D1: ← Về Tổng quan
A2: Miền: | B2: Miền Bắc
A3: Tỉnh/TP (mới): | B3: Hà Nội
A4: Tỉnh/TP (cũ): | B4: Hà Nội
A5: Trang chủ: | B5: https://hup.edu.vn/
A6: Trang tuyển sinh: | B6: https://tuyensinh.hup.edu.vn/
A7: Nguồn/ghi chú: | B7: Danh sách ngành chính quy 2025-2026. Nguồn: đề án HUP. Cập nhật 10/2026.
A10: STT | B10: Mã ngành | C10: Tên ngành (hệ chính quy)
A11: 1 | B11: 7720201 | C11: Dược học
A12: 2 | B12: 7720203 | C12: Hóa dược
A13: 3 | B13: 7440112 | C13: Hóa học
A14: 4 | B14: 7420201 | C14: Công nghệ sinh học

Sheet HUPH
A1: Đại học Y tế Công cộng (HUPH) | D1: ← Về Tổng quan
A2: Miền: | B2: Miền Bắc
A3: Tỉnh/TP (mới): | B3: Hà Nội
A4: Tỉnh/TP (cũ): | B4: Hà Nội
A5: Trang chủ: | B5: https://huph.edu.vn/
A6: Trang tuyển sinh: | B6: https://tuyensinh.huph.edu.vn/
A7: Nguồn/ghi chú: | B7: Danh sách ngành chính quy 2026. Nguồn: các trang tuyển sinh HUPH. Cập nhật 10/2026.
A10: STT | B10: Mã ngành | C10: Tên ngành (hệ chính quy)
A11: 1 | B11: 7460108 | C11: Khoa học dữ liệu
A12: 2 | B12: 7720401 | C12: Dinh dưỡng
A13: 3 | B13: 7720601 | C13: Kỹ thuật xét nghiệm y học
A14: 4 | B14: 7720603 | C14: Kỹ thuật phục hồi chức năng
A15: 5 | B15: 7720701 | C15: Y tế công cộng
A16: 6 | B16: 7760101 | C16: Công tác xã hội

Sheet HUC
A1: Trường Đại học Văn hóa Hà Nội (HUC) | D1: ← Về Tổng quan
A2: Miền: | B2: Miền Bắc
A3: Tỉnh/TP (mới): | B3: Hà Nội
A4: Tỉnh/TP (cũ): | B4: Hà Nội
A5: Trang chủ: | B5: https://huc.edu.vn/
A6: Trang tuyển sinh: | B6: https://tuyensinh.huc.edu.vn/
A7: Nguồn/ghi chú: | B7: Danh sách ngành/chuyên ngành chính quy 2026. Nguồn: các trang tuyển sinh HUC. Cập nhật 10/2026.
A10: STT | B10: Mã ngành | C10: Tên ngành (hệ chính quy)
A11: 1 | B11: 7220110 | C11: Sáng tác văn học
A12: 2 | B12: 7220201 | C12: Ngôn ngữ Anh
A13: 3 | B13: 7229040A | C13: Nghiên cứu văn hóa
A14: 4 | B14: 7229040B | C14: Văn hóa truyền thông
A15: 5 | B15: 7229040C | C15: Văn hóa đối ngoại
A16: 6 | B16: 7229042A | C16: Phát triển công nghiệp văn hóa
A17: 7 | B17: 7229042B | C17: Quản lý di sản văn hóa
A18: 8 | B18: 7229042C | C18: Tổ chức hoạt động nghệ thuật
A19: 9 | B19: 7229042D | C19: Tổ chức sự kiện văn hóa
A20: 10 | B20: 7320101 | C20: Báo chí
A21: 11 | B21: 7320201A | C21: Quản trị thư viện
A22: 12 | B22: 7320201B | C22: Thư viện và thiết bị trường học
... A31: 21 | B31: 7810103B | C31: Quản trị du lịch cộng đồng

Sheet HOU
A1: Trường Đại học Mở Hà Nội (HOU) | D1: ← Về Tổng quan
A2: Miền: | B2: Miền Bắc
A3: Tỉnh/TP (mới): | B3: Hà Nội
A4: Tỉnh/TP (cũ): | B4: Hà Nội
A5: Trang chủ: | B5: https://hou.edu.vn/
A6: Trang tuyển sinh: | B6: https://tuyensinh.hou.edu.vn/
A7: Nguồn/ghi chú: | B7: Danh sách ngành chính quy 2026. Nguồn: các trang tuyển sinh HOU. Cập nhật 10/2026.
A10: STT | B10: Mã ngành | C10: Tên ngành (hệ chính quy)
A11: 1 | B11: 7210403 | C11: Thiết kế đồ họa
A12: 2 | B12: 7210404 | C12: Thiết kế thời trang
A13: 3 | B13: 7220201 | C13: Ngôn ngữ Anh
A14: 4 | B14: 7220204 | C14: Ngôn ngữ Trung Quốc
A15: 5 | B15: 7340101 | C15: Quản trị kinh doanh
A16: 6 | B16: 7340122 | C16: Thương mại điện tử
A17: 7 | B17: 7340201 | C17: Tài chính - Ngân hàng
A18: 8 | B18: 7340204 | C18: Bảo hiểm
A19: 9 | B19: 7340301 | C19: Kế toán
A20: 10 | B20: 7380101 | C20: Luật
A21: 11 | B21: 7380107 | C21: Luật kinh tế
A22: 12 | B22: 7380108 | C22: Luật quốc tế
... A32: 22 | B32: 7810201 | C32: Quản trị khách sạn

Sheet ULSA
A1: Trường Đại học Lao động - Xã hội (ULSA) | D1: ← Về Tổng quan
A2: Miền: | B2: Miền Bắc
A3: Tỉnh/TP (mới): | B3: Hà Nội
A4: Tỉnh/TP (cũ): | B4: Hà Nội
A5: Trang chủ: | B5: https://ulsa.edu.vn/
A6: Trang tuyển sinh: | B6: https://tuyensinh.ulsa.edu.vn/
A7: Nguồn/ghi chú: | B7: Danh sách ngành chính quy 2025-2026. Nguồn: các trang tuyển sinh ULSA. Cập nhật 10/2026.
A10: STT | B10: Mã ngành | C10: Tên ngành (hệ chính quy)
A11: 1 | B11: 7220201 | C11: Ngôn ngữ Anh
A12: 2 | B12: 7310101 | C12: Kinh tế
A13: 3 | B13: 7310401 | C13: Tâm lý học
A14: 4 | B14: 7340101 | C14: Quản trị kinh doanh
A15: 5 | B15: 7340201 | C15: Tài chính - Ngân hàng
A16: 6 | B16: 7340204 | C16: Bảo hiểm
A17: 7 | B17: 7340207 | C17: Bảo hiểm - Tài chính
A18: 8 | B18: 7340301 | C18: Kế toán
A19: 9 | B19: 7340302 | C19: Kiểm toán
A20: 10 | B20: 7340404 | C20: Quản trị nhân lực
A21: 11 | B21: 7340405 | C21: Hệ thống thông tin quản lý
A22: 12 | B22: 7380107 | C22: Luật kinh tế
... A25: 15 | B25: 7810103 | C25: Quản trị dịch vụ du lịch và Lữ hành

Sheet UTC
A1: Trường Đại học Giao thông Vận tải (UTC) | D1: ← Về Tổng quan
A2: Miền: | B2: Miền Bắc
A3: Tỉnh/TP (mới): | B3: Hà Nội
A4: Tỉnh/TP (cũ): | B4: Hà Nội
A5: Trang chủ: | B5: https://utc.edu.vn/
A6: Trang tuyển sinh: | B6: https://tuyensinh.utc.edu.vn/
A7: Nguồn/ghi chú: | B7: Danh sách ngành chính quy 2026. Nguồn: các trang tuyển sinh UTC. Cập nhật 10/2026.
A10: STT | B10: Mã ngành | C10: Tên ngành (hệ chính quy)
A11: 1 | B11: 7220201 | C11: Ngôn ngữ Anh
A12: 2 | B12: 7460112 | C12: Toán ứng dụng
A13: 3 | B13: 7310101 | C13: Kinh tế
A14: 4 | B14: 7340101 | C14: Quản trị kinh doanh
A15: 5 | B15: 7340201 | C15: Tài chính - Ngân hàng
A16: 6 | B16: 7340301 | C16: Kế toán
A17: 7 | B17: 7510605 | C17: Logistics và Quản lý chuỗi cung ứng
A18: 8 | B18: 7810103 | C18: Quản trị dịch vụ du lịch và lữ hành
A19: 9 | B19: 7840101 | C19: Khai thác vận tải
A20: 10 | B20: 7840104 | C20: Kinh tế vận tải
A21: 11 | B21: 7580301 | C21: Kinh tế xây dựng
A22: 12 | B22: 7580302 | C22: Quản lý xây dựng
... A41: 31 | B41: 7580210 | C41: Kỹ thuật cơ sở hạ tầng

Sheet USTH
A1: Trường Đại học Khoa học và Công nghệ Hà Nội (USTH) | D1: ← Về Tổng quan
A2: Miền: | B2: Miền Bắc
A3: Tỉnh/TP (mới): | B3: Hà Nội
A4: Tỉnh/TP (cũ): | B4: Hà Nội
A5: Trang chủ: | B5: https://usth.edu.vn/
A6: Trang tuyển sinh: | B6: https://tuyensinh.usth.edu.vn/
A7: Nguồn/ghi chú: | B7: Danh sách ngành chính quy 2026. Nguồn: tuyensinh.usth.edu.vn. Cập nhật 10/2026.
A10: STT | B10: Mã ngành | C10: Tên ngành (hệ chính quy)
A11: 1 | B11: 7420201 | C11: Công nghệ sinh học – Phát triển thuốc
A12: 2 | B12: 7440112 | C12: Hóa học
A13: 3 | B13: 7440122 | C13: Khoa học vật liệu tiên tiến và Công nghệ Nano
A14: 4 | B14: 7440301 | C14: Khoa học Môi trường Ứng dụng
A15: 5 | B15: 7460108 | C15: Khoa học dữ liệu
A16: 6 | B16: 7460112 | C16: Toán ứng dụng
A17: 7 | B17: 7480201 | C17: Công nghệ thông tin – Truyền thông
A18: 8 | B18: 7480202 | C18: An toàn thông tin
A19: 9 | B19: 7510203 | C19: Công nghệ Kỹ thuật Cơ điện tử
A20: 10 | B20: 7520120 | C20: Kỹ thuật Hàng không
A21: 11 | B21: 7520121 | C21: Khoa học Vũ trụ và Công nghệ Vệ tinh
A22: 12 | B22: 7520130 | C22: Kỹ thuật ô tô
... A27: 17 | B27: 7720201 | C27: Dược học

Sheet Phenikaa
A1: Trường Đại học Phenikaa | D1: ← Về Tổng quan
A2: Miền: | B2: Miền Bắc
A3: Tỉnh/TP (mới): | B3: Hà Nội
A4: Tỉnh/TP (cũ): | B4: Hà Nội
A5: Trang chủ: | B5: https://phenikaa-uni.edu.vn/
A6: Trang tuyển sinh: | B6: https://tuyensinh.phenikaa-uni.edu.vn/
A7: Nguồn/ghi chú: | B7: Danh sách một số ngành chính quy tiêu biểu 2025-2026 (trường có nhiều chương trình). Nguồn: các trang tuyển sinh Phenikaa. Cập nhật 10/2026.
A10: STT | B10: Mã ngành | C10: Tên ngành (hệ chính quy)
A11: 1 | B11: BIO1 | C11: Công nghệ sinh học
A12: 2 | B12: BMS | C12: Khoa học y sinh
A13: 3 | B13: CHE1 | C13: Kỹ thuật hóa học
A14: 4 | B14: DEN1 | C14: Răng - Hàm - Mặt
A15: 5 | B15: EEE1 | C15: Kỹ thuật điều khiển và tự động hóa
A16: 6 | B16: EEE-AI | C16: Kỹ thuật điều khiển và tự động hóa (Robot và AI)
A17: 7 | B17: EEE2 | C17: Kỹ thuật y sinh (Điện tử y sinh)
A18: 8 | B18: FBE1 | C18: Quản trị kinh doanh
A19: 9 | B19: FBE2 | C19: Kế toán
A20: 10 | B20: FBE3 | C20: Tài chính – ngân hàng
A21: 11 | B21: FBE4 | C21: Quản trị nhân lực
A22: 12 | B22: FLE1 | C22: Ngôn ngữ Anh
... A26: 16 | B26: FTS1 | C26: Du lịch

Sheet Thăng Long
A1: Trường Đại học Thăng Long | D1: ← Về Tổng quan
A2: Miền: | B2: Miền Bắc
A3: Tỉnh/TP (mới): | B3: Hà Nội
A4: Tỉnh/TP (cũ): | B4: Hà Nội
A5: Trang chủ: | B5: https://thanglong.edu.vn/
A6: Trang tuyển sinh: | B6: https://tuyensinh.thanglong.edu.vn/
A7: Nguồn/ghi chú: | B7: Danh sách ngành chính quy 2026. Nguồn: đề án và các trang tuyển sinh Thăng Long. Cập nhật 10/2026.
A10: STT | B10: Mã ngành | C10: Tên ngành (hệ chính quy)
A11: 1 | B11: 7210205 | C11: Thanh nhạc
A12: 2 | B12: 7210403 | C12: Thiết kế đồ họa
A13: 3 | B13: 7220201 | C13: Ngôn ngữ Anh
A14: 4 | B14: 7220204 | C14: Ngôn ngữ Trung Quốc
A15: 5 | B15: 7220209 | C15: Ngôn ngữ Nhật
A16: 6 | B16: 7220210 | C16: Ngôn ngữ Hàn Quốc
A17: 7 | B17: 7310106 | C17: Kinh tế quốc tế
A18: 8 | B18: 7310630 | C18: Việt Nam học
A19: 9 | B19: 7320104 | C19: Truyền thông đa phương tiện
A20: 10 | B20: 7340101 | C20: Quản trị kinh doanh
A21: 11 | B21: 7340115 | C21: Marketing
A22: 12 | B22: 7340122 | C22: Thương mại điện tử
... A32: 22 | B32: 7810201 | C32: Quản trị khách sạn

Sheet CMC
A1: Trường Đại học CMC | D1: ← Về Tổng quan
A2: Miền: | B2: Miền Bắc
A3: Tỉnh/TP (mới): | B3: Hà Nội
A4: Tỉnh/TP (cũ): | B4: Hà Nội
A5: Trang chủ: | B5: https://cmc-u.edu.vn/
A6: Trang tuyển sinh: | B6: https://tuyensinh.cmc-u.edu.vn/
A7: Nguồn/ghi chú: | B7: Danh sách ngành chính quy 2025-2026. Nguồn: các trang tuyển sinh CMC. Cập nhật 10/2026.
A10: STT | B10: Mã ngành | C10: Tên ngành (hệ chính quy)
A11: 1 | B11: AI | C11: Trí tuệ nhân tạo
A12: 2 | B12: BA | C12: Quản trị Kinh doanh
A13: 3 | B13: CL | C13: Ngôn ngữ Trung Quốc
A14: 4 | B14: CS | C14: Khoa học Máy tính
A15: 5 | B15: EC | C15: Thương mại điện tử
A16: 6 | B16: ET | C16: Công nghệ kỹ thuật Điện tử – Viễn thông
A17: 7 | B17: GA | C17: Đồ họa game
A18: 8 | B18: GD | C18: Thiết kế Đồ họa
A19: 9 | B19: IT | C19: Công nghệ Thông tin
A20: 10 | B20: JL | C20: Tiếng Nhật thương mại
A21: 11 | B21: KL | C21: Ngôn ngữ Hàn Quốc
A22: 12 | B22: LS | C22: Logistics & Quản lý chuỗi cung ứng
... A24: 14 | B24: SE | C24: Kỹ thuật phần mềm

Sheet Đại Nam
A1: Trường Đại học Đại Nam | D1: ← Về Tổng quan
A2: Miền: | B2: Miền Bắc
A3: Tỉnh/TP (mới): | B3: Hà Nội
A4: Tỉnh/TP (cũ): | B4: Hà Nội
A5: Trang chủ: | B5: https://dainam.edu.vn/
A6: Trang tuyển sinh: | B6: https://tuyensinh.dainam.edu.vn/
A7: Nguồn/ghi chú: | B7: Danh sách ngành chính quy tiêu biểu 2026. Nguồn: dainam.edu.vn. Cập nhật 10/2026.
A10: STT | B10: Mã ngành | C10: Tên ngành (hệ chính quy)
A11: 1 | B11: Y khoa | C11: Y khoa
A12: 2 | B12: Dược học | C12: Dược học
A13: 3 | B13: Điều dưỡng | C13: Điều dưỡng
A14: 4 | B14: 7480201 | C14: Công nghệ thông tin
A15: 5 | B15: 7480101 | C15: Khoa học máy tính
A16: 6 | B16: 7480104 | C16: Hệ thống thông tin
A17: 7 | B17: 7510205 | C17: Công nghệ kỹ thuật ô tô
A18: 8 | B18: 7510301 | C18: Công nghệ kỹ thuật điện - điện tử
A19: 9 | B19: 7510203 | C19: Công nghệ kỹ thuật cơ điện tử
A20: 10 | B20: 7580101 | C20: Kiến trúc
A21: 11 | B21: 7580201 | C21: Kỹ thuật xây dựng
A22: 12 | B22: 7580301 | C22: Kinh tế xây dựng
... A36: 26 | B36: 7380101 | C36: Luật

Sheet HUBT
A1: Trường Đại học Kinh doanh và Công nghệ Hà Nội (HUBT) | D1: ← Về Tổng quan
A2: Miền: | B2: Miền Bắc
A3: Tỉnh/TP (mới): | B3: Hà Nội
A4: Tỉnh/TP (cũ): | B4: Hà Nội
A5: Trang chủ: | B5: https://hubt.edu.vn/
A6: Trang tuyển sinh: | B6: https://tuyensinh.hubt.edu.vn/
A7: Nguồn/ghi chú: | B7: Danh sách ngành chính quy 2025-2026. Nguồn: các trang tuyển sinh HUBT. Cập nhật 10/2026.
A10: STT | B10: Mã ngành | C10: Tên ngành (hệ chính quy)
A11: 1 | B11: 7210403 | C11: Thiết kế đồ họa
A12: 2 | B12: 7220201 | C12: Ngôn ngữ Anh
A13: 3 | B13: 7220202 | C13: Ngôn ngữ Nga
A14: 4 | B14: 7220204 | C14: Ngôn ngữ Trung Quốc
A15: 5 | B15: 7310101 | C15: Kinh tế
A16: 6 | B16: 7310205 | C16: Quản lý nhà nước
A17: 7 | B17: 7340101 | C17: Quản trị kinh doanh
A18: 8 | B18: 7340120 | C18: Kinh doanh quốc tế
A19: 9 | B19: 7340201 | C19: Tài chính – Ngân hàng
A20: 10 | B20: 7340301 | C20: Kế toán
A21: 11 | B21: 7380107 | C21: Luật kinh tế
A22: 12 | B22: 7480201 | C22: Công nghệ thông tin
... A35: 25 | B35: 7810103 | C35: Quản trị dịch vụ du lịch và lữ hành

Sheet Việt - Hung (VIU)
A1: Trường Đại học Công nghiệp Việt - Hung | D1: ← Về Tổng quan
A2: Miền: | B2: Miền Bắc
A3: Tỉnh/TP (mới): | B3: Hà Nội
A4: Tỉnh/TP (cũ): | B4: Hà Nội
A5: Trang chủ: | B5: https://viu.edu.vn/
A6: Trang tuyển sinh: | B6: https://tuyensinh.viu.edu.vn/
A7: Nguồn/ghi chú: | B7: Danh sách ngành chính quy 2025. Nguồn: các trang tuyển sinh VIU. Cập nhật 10/2026.
A10: STT | B10: Mã ngành | C10: Tên ngành (hệ chính quy)
A11: 1 | B11: 7310101 | C11: Kinh tế
A12: 2 | B12: 7310109 | C12: Kinh tế số
A13: 3 | B13: 7340101 | C13: Quản trị kinh doanh
A14: 4 | B14: 7340115 | C14: Marketing
A15: 5 | B15: 7340201 | C15: Tài chính – Ngân hàng
A16: 6 | B16: 7340205 | C16: Công nghệ tài chính
A17: 7 | B17: 7480101 | C17: Khoa học máy tính
A18: 8 | B18: 7480201 | C18: Công nghệ thông tin
A19: 9 | B19: 7510103 | C19: Công nghệ kỹ thuật xây dựng
A20: 10 | B20: 7510201 | C20: Công nghệ kỹ thuật cơ khí
A21: 11 | B21: 7510205 | C21: Công nghệ kỹ thuật ô tô
A22: 12 | B22: 7510301 | C22: Công nghệ kỹ thuật điện, điện tử
A23: 13 | B23: 7510302 | C23: Công nghệ kỹ thuật điện tử viễn thông

Sheet MTA
A1: Học viện Kỹ thuật Quân sự (MTA) | D1: ← Về Tổng quan
A2: Miền: | B2: Miền Bắc
A3: Tỉnh/TP (mới): | B3: Hà Nội
A4: Tỉnh/TP (cũ): | B4: Hà Nội
A5: Trang chủ: | B5: https://mta.edu.vn/
A6: Trang tuyển sinh: | B6: https://mta.edu.vn/ (mục Tuyển sinh)
A7: Nguồn/ghi chú: | B7: Danh sách ngành chính quy 2026 (hệ Quân sự + Dân sự). Nguồn: các trang tuyển sinh MTA. Cập nhật 10/2026.
A10: STT | B10: Mã ngành | C10: Tên ngành (hệ chính quy)
A11: 1 | B11: 7860220 | C11: Kỹ sư quân sự (hệ Quân sự)
A12: 2 | B12: 7480201 | C12: Công nghệ thông tin (hệ Dân sự)
A13: 3 | B13: 7480101 | C13: Khoa học máy tính / Trí tuệ nhân tạo (hệ Dân sự)
A14: 4 | B14: 7480202 | C14: An toàn thông tin (hệ Dân sự)
A15: 5 | B15: 7520207 | C15: Kỹ thuật điện tử – viễn thông (hệ Dân sự)
A16: 6 | B16: 7520216 | C16: Kỹ thuật điều khiển và tự động hóa (hệ Dân sự)
A17: 7 | B17: 7520114 | C17: Kỹ thuật cơ điện tử (hệ Dân sự)
A18: 8 | B18: 7520103 | C18: Kỹ thuật cơ khí (hệ Dân sự)
A19: 9 | B19: 7580201 | C19: Kỹ thuật xây dựng (hệ Dân sự)
A20: 10 | B20: 7520116 | C20: Kỹ thuật cơ khí động lực / ô tô (hệ Dân sự)

Sheet HV Quân y
A1: Học viện Quân y | D1: ← Về Tổng quan
A2: Miền: | B2: Miền Bắc
A3: Tỉnh/TP (mới): | B3: Hà Nội
A4: Tỉnh/TP (cũ): | B4: Hà Nội
A5: Trang chủ: | B5: https://hvqy.edu.vn/
A6: Trang tuyển sinh: | B6: https://tuyensinh.hvqy.edu.vn/
A7: Nguồn/ghi chú: | B7: Danh sách ngành chính quy 2025-2026. Nguồn: thông báo tuyển sinh HV Quân y. Cập nhật 10/2026.
A10: STT | B10: Mã ngành | C10: Tên ngành (hệ chính quy)
A11: 1 | B11: 7720101 | C11: Y khoa (hệ Quân sự + Dân sự)
A12: 2 | B12: 7720201 | C12: Dược học (hệ Quân sự + Dân sự)

Sheet HV KH Quân sự
A1: Học viện Khoa học Quân sự | D1: ← Về Tổng quan
A2: Miền: | B2: Miền Bắc
A3: Tỉnh/TP (mới): | B3: Hà Nội
A4: Tỉnh/TP (cũ): | B4: Hà Nội
A5: Trang chủ: | B5: https://hocvienkhoahocquan.su.edu.vn/ hoặc trang Bộ Quốc phòng
A6: Trang tuyển sinh: | B6: Trang tuyển sinh quân sự chung
A7: Nguồn/ghi chú: | B7: Danh sách ngành chính quy hệ Quân sự 2025-2026. Nguồn: thông báo tuyển sinh HV KHQS. Cập nhật 10/2026.
A10: STT | B10: Mã ngành | C10: Tên ngành (hệ chính quy)
A11: 1 | B11: 7860231 | C11: Trinh sát Kỹ thuật
A12: 2 | B12: 7220201 | C12: Ngôn ngữ Anh
A13: 3 | B13: 7220202 | C13: Ngôn ngữ Nga
A14: 4 | B14: 7220204 | C14: Ngôn ngữ Trung Quốc
A15: 5 | B15: 7310206 | C15: Quan hệ quốc tế

Sheet HV Biên phòng
A1: Học viện Biên phòng | D1: ← Về Tổng quan
A2: Miền: | B2: Miền Bắc
A3: Tỉnh/TP (mới): | B3: Hà Nội
A4: Tỉnh/TP (cũ): | B4: Hà Nội
A5: Trang chủ: | B5: https://hocvienbienphong.edu.vn/
A6: Trang tuyển sinh: | B6: Trang tuyển sinh quân sự
A7: Nguồn/ghi chú: | B7: Danh sách ngành chính quy 2026. Nguồn: thông tin tuyển sinh HV Biên phòng. Cập nhật 10/2026.
A10: STT | B10: Mã ngành | C10: Tên ngành (hệ chính quy)
A11: 1 | B11: 7860214 | C11: Biên phòng
A12: 2 | B12: 7380101 | C12: Luật

Sheet HV Hậu cần
A1: Học viện Hậu cần | D1: ← Về Tổng quan
A2: Miền: | B2: Miền Bắc
A3: Tỉnh/TP (mới): | B3: Hà Nội
A4: Tỉnh/TP (cũ): | B4: Hà Nội
A5: Trang chủ: | B5: https://hocvienhaucan.edu.vn/
A6: Trang tuyển sinh: | B6: Trang tuyển sinh quân sự
A7: Nguồn/ghi chú: | B7: Danh sách ngành chính quy 2025-2026 (hệ Quân sự + Dân sự). Nguồn: đề án tuyển sinh. Cập nhật 10/2026.
A10: STT | B10: Mã ngành | C10: Tên ngành (hệ chính quy)
A11: 1 | B11: 7860218 | C11: Hậu cần quân sự (hệ Quân sự)
A12: 2 | B12: 7340201 | C12: Tài chính - Ngân hàng (hệ Dân sự)
A13: 3 | B13: 7340301 | C13: Kế toán (hệ Dân sự)
A14: 4 | B14: 7580201 | C14: Kỹ thuật xây dựng (hệ Dân sự)

Sheet HV PK-KQ
A1: Học viện Phòng không - Không quân | D1: ← Về Tổng quan
A2: Miền: | B2: Miền Bắc
A3: Tỉnh/TP (mới): | B3: Hà Nội
A4: Tỉnh/TP (cũ): | B4: Hà Nội
A5: Trang chủ: | B5: https://hocvienpkkq.edu.vn/
A6: Trang tuyển sinh: | B6: Trang tuyển sinh quân sự
A7: Nguồn/ghi chú: | B7: Danh sách ngành chính quy 2026. Nguồn: thông tin tuyển sinh HV PK-KQ. Cập nhật 10/2026.
